/*****************************Ejercicio 1. Practique el uso de asyn y await*******************************/

import 'dart:async';
import 'dart:math';

// Parte 1: Implementar reportUserRole()
Future<String> reportUserRole() async {
  String role = await fetchRole();
  return 'User role: $role';
}

// Parte 2: Implementar reportLogins()
Future<String> reportLogins() async {
  int logins = await fetchLoginAmount();
  return 'Total number of logins: $logins';
}

// Parte 3: Implementar changeUsername()
Future<String> changeUsername() async {
  try {
    return await fetchNewUsername();
  } catch (err) {
    return err.toString();
  }
}

// Función simulada para obtener el rol del usuario
Future<String> fetchRole() => Future.delayed(_halfSecond, () => _role);

// Función simulada para obtener la cantidad de inicios de sesión
Future<int> fetchLoginAmount() => Future.delayed(_halfSecond, () => _logins);

// Función para obtener un nuevo nombre de usuario
Future<String> fetchNewUsername() async {
  await Future.delayed(Duration(seconds: 1));
  return 'new_username';
}

const _role = 'administrator';
const _logins = 42;
const _halfSecond = Duration(milliseconds: 500);

void main() async {
  print('Testing...');
  List<String> messages = [];
  const passed = 'PASSED';
  const testFailedMessage = 'Test failed for the function:';
  const typoMessage = 'Test failed! Check for typos in your return value';
  try {
    messages
      ..add(_makeReadable(
          testLabel: 'Part 1',
          testResult: await _asyncEquals(
            expected: 'User role: administrator',
            actual: await reportUserRole(),
            typoKeyword: _role,
          ),
          readableErrors: {
            typoMessage: typoMessage,
            'null':
                'Test failed! Did you forget to implement or return from reportUserRole?',
            'User role: Instance of \'Future<String>\'':
                '$testFailedMessage reportUserRole. Did you use the await keyword?',
            'User role: Instance of \'_Future<String>\'':
                '$testFailedMessage reportUserRole. Did you use the await keyword?',
            'User role:':
                '$testFailedMessage reportUserRole. Did you return a user role?',
            'User role: ':
                '$testFailedMessage reportUserRole. Did you return a user role?',
            'User role: tester':
                '$testFailedMessage reportUserRole. Did you invoke fetchRole to fetch the user\'s role?',
          }))
      ..add(_makeReadable(
          testLabel: 'Part 2',
          testResult: await _asyncEquals(
            expected: 'Total number of logins: 42',
            actual: await reportLogins(),
            typoKeyword: _logins.toString(),
          ),
          readableErrors: {
            typoMessage: typoMessage,
            'null':
                'Test failed! Did you forget to implement or return from reportLogins?',
            'Total number of logins: Instance of \'Future<int>\'':
                '$testFailedMessage reportLogins. Did you use the await keyword?',
            'Total number of logins: Instance of \'_Future<int>\'':
                '$testFailedMessage reportLogins. Did you use the await keyword?',
            'Total number of logins: ':
                '$testFailedMessage reportLogins. Did you return the number of logins?',
            'Total number of logins:':
                '$testFailedMessage reportLogins. Did you return the number of logins?',
            'Total number of logins: 57':
                '$testFailedMessage reportLogins. Did you invoke fetchLoginAmount to fetch the number of user logins?',
          }))
      ..add(_makeReadable(
          testLabel: 'Part 3',
          testResult: await _asyncEquals(
            expected: 'new_username',
            actual: await changeUsername(),
            typoKeyword: 'new_username',
          ),
          readableErrors: {
            typoMessage: typoMessage,
            'null':
                'Test failed! Did you forget to implement or return from changeUsername?',
            'new_username':
                'Test failed! Did you invoke fetchNewUsername to fetch the new username?',
          }))
      ..removeWhere((m) => m.contains(passed))
      ..toList();

    if (messages.isEmpty) {
      print('Success. All tests passed!');
    } else {
      messages.forEach(print);
    }
  } on UnimplementedError {
    print(
        'Test failed! Did you forget to implement or return from one of the functions?');
  } catch (e) {
    print('Tried to run solution, but received an exception: $e');
  }
}

String _makeReadable({
  required String testResult,
  required Map<String, String> readableErrors,
  required String testLabel,
}) {
  if (readableErrors.containsKey(testResult)) {
    var readable = readableErrors[testResult];
    return '$testLabel $readable';
  } else {
    return '$testLabel $testResult';
  }
}

Future<String> _asyncEquals({
  required String expected,
  required dynamic actual,
  required String typoKeyword,
}) async {
  var strActual = actual is String ? actual : actual.toString();
  try {
    if (expected == actual) {
      return 'PASSED';
    } else if (strActual.contains(typoKeyword)) {
      return 'Test failed! Check for typos in your return value';
    } else {
      return strActual;
    }
  } catch (e) {
    return e.toString();
  }
}
 
/*****************************Ejercicio 2. Practique el manejo de errores*******************************/

import 'dart:async';

// Implementar changeUsername 
Future<String> changeUsername() async {
  try {
    return await fetchNewUsername();
  } catch (err) {
    return err.toString();
  }
}

Future<String> fetchNewUsername() =>
    Future.delayed(const Duration(milliseconds: 500), () => throw UserError());

class UserError implements Exception {
  @override
  String toString() => 'New username is invalid';
}

void main() async {
  final List<String> messages = [];
  const typoMessage = 'Test failed! Check for typos in your return value';

  print('Testing...');
  try {
    messages
      ..add(_makeReadable(
          testLabel: '',
          testResult: await _asyncDidCatchException(changeUsername),
          readableErrors: {
            typoMessage: typoMessage,
            _noCatch:
                'Did you remember to call fetchNewUsername within a try/catch block?',
          }))
      ..add(_makeReadable(
          testLabel: '',
          testResult: await _asyncErrorEquals(changeUsername),
          readableErrors: {
            typoMessage: typoMessage,
            _noCatch:
                'Did you remember to call fetchNewUsername within a try/catch block?',
          }))
      ..removeWhere((m) => m.contains(_passed))
      ..toList();

    if (messages.isEmpty) {
      print('Success. All tests passed!');
    } else {
      messages.forEach(print);
    }
  } catch (e) {
    print('Tried to run solution, but received an exception: $e');
  }
}

// Test helpers.
String _makeReadable({
  required String testResult,
  required Map<String, String> readableErrors,
  required String testLabel,
}) {
  if (readableErrors.containsKey(testResult)) {
    final readable = readableErrors[testResult];
    return '$testLabel $readable';
  } else {
    return '$testLabel $testResult';
  }
}

Future<String> _asyncErrorEquals(Function fn) async {
  final result = await fn();
  if (result == UserError().toString()) {
    return _passed;
  } else {
    return 'Test failed! Did you stringify and return the caught error?';
  }
}

Future<String> _asyncDidCatchException(Function fn) async {
  var caught = true;
  try {
    await fn();
  } on UserError catch (_) {
    caught = false;
  }

  if (caught == false) {
    return _noCatch;
  } else {
    return _passed;
  }
}

const _passed = 'PASSED';
const _noCatch = 'NO_CATCH';

/**********************************************Ejercicio 3.************************************************/

import 'dart:async';

// Parte 1
String addHello(String user) => 'Hello $user';

// Parte 2
// Llama a la función asincrónica proporcionada fetchUsername() para devolver el nombre de usuario.
Future<String> greetUser() async {
  final username = await fetchUsername();
  return addHello(username);
}

// Parte 3
// Llama a la función asincrónica proporcionada logoutUser() para cerrar la sesión del usuario.
Future<String> sayGoodbye() async {
  try {
    final result = await logoutUser();
    return '$result Thanks, see you next time';
  } catch (e) {
    return 'Failed to logout user: $e';
  }
}

Future<String> fetchUsername() => Future.delayed(_halfSecond, () => 'Jean');

Future<String> logoutUser() => Future.delayed(_halfSecond, _failOnce);

void main() async {
  const didNotImplement =
      'Test failed! Did you forget to implement or return from';

  final List<String> messages = [];

  print('Testing...');
  try {
    messages
      ..add(_makeReadable(
          testLabel: 'Part 1',
          testResult: await _asyncEquals(
              expected: 'Hello Jerry',
              actual: addHello('Jerry'),
              typoKeyword: 'Jerry'),
          readableErrors: {
            _typoMessage: _typoMessage,
            'null': '$didNotImplement addHello?',
            'Hello Instance of \'Future<String>\'':
                'Looks like you forgot to use the \'await\' keyword!',
            'Hello Instance of \'_Future<String>\'':
                'Looks like you forgot to use the \'await\' keyword!',
          }))
      ..add(_makeReadable(
          testLabel: 'Part 2',
          testResult: await _asyncEquals(
              expected: 'Hello Jean',
              actual: await greetUser(),
              typoKeyword: 'Jean'),
          readableErrors: {
            _typoMessage: _typoMessage,
            'null': '$didNotImplement greetUser?',
            'HelloJean':
                'Looks like you forgot the space between \'Hello\' and \'Jean\'',
            'Hello Instance of \'Future<String>\'':
                'Looks like you forgot to use the \'await\' keyword!',
            'Hello Instance of \'_Future<String>\'':
                'Looks like you forgot to use the \'await\' keyword!',
            '{Closure: (String) => dynamic from Function \'addHello\': static.(await fetchUsername())}':
                'Did you place the \'\$\' character correctly?',
            '{Closure \'addHello\'(await fetchUsername())}':
                'Did you place the \'\$\' character correctly?',
          }))
      ..add(_makeReadable(
          testLabel: 'Part 3',
          testResult: await _asyncDidCatchException(sayGoodbye),
          readableErrors: {
            _typoMessage:
                '$_typoMessage. Did you add the text \'Thanks, see you next time\'?',
            'null': '$didNotImplement sayGoodbye?',
            _noCatch:
                'Did you remember to call logoutUser within a try/catch block?',
            'Instance of \'Future<String>\' Thanks, see you next time':
                'Did you remember to use the \'await\' keyword in the sayGoodbye function?',
            'Instance of \'_Future<String>\' Thanks, see you next time':
                'Did you remember to use the \'await\' keyword in the sayGoodbye function?',
          }))
      ..add(_makeReadable(
          testLabel: 'Part 3',
          testResult: await _asyncEquals(
              expected: 'Success! Thanks, see you next time',
              actual: await sayGoodbye(),
              typoKeyword: 'Success'),
          readableErrors: {
            _typoMessage:
                '$_typoMessage. Did you add the text \'Thanks, see you next time\'?',
            'null': '$didNotImplement sayGoodbye?',
            _noCatch:
                'Did you remember to call logoutUser within a try/catch block?',
            'Instance of \'Future<String>\' Thanks, see you next time':
                'Did you remember to use the \'await\' keyword in the sayGoodbye function?',
            'Instance of \'_Future<String>\' Thanks, see you next time':
                'Did you remember to use the \'await\' keyword in the sayGoodbye function?',
            'Instance of \'_Exception\'':
                'CAUGHT Did you remember to return a string?',
          }))
      ..removeWhere((m) => m.contains(_passed))
      ..toList();

    if (messages.isEmpty) {
      print('Success. All tests passed!');
    } else {
      messages.forEach(print);
    }
  } catch (e) {
    print('Tried to run solution, but received an exception: $e');
  }
}

// Test Helpers
String _makeReadable({
  required String testResult,
  required Map<String, String> readableErrors,
  required String testLabel,
}) {
  String? readable;
  if (readableErrors.containsKey(testResult)) {
    readable = readableErrors[testResult];
    return '$testLabel $readable';
  } else if ((testResult != _passed) && (testResult.length < 18)) {
    readable = _typoMessage;
    return '$testLabel $readable';
  } else {
    return '$testLabel $testResult';
  }
}

Future<String> _asyncEquals({
  required String expected,
  required dynamic actual,
  required String typoKeyword,
}) async {
  final strActual = actual is String ? actual : actual.toString();
  try {
    if (expected == actual) {
      return _passed;
    } else if (strActual.contains(typoKeyword)) {
      return _typoMessage;
    } else {
      return strActual;
    }
  } catch (e) {
    return e.toString();
  }
}

Future<String> _asyncDidCatchException(Function fn) async {
  var caught = true;
  try {
    await fn();
  } on Exception catch (_) {
    caught = false;
  }

  if (caught == true) {
    return _passed;
  } else {
    return _noCatch;
  }
}

const _typoMessage = 'Test failed! Check for typos in your return value';
const _passed = 'PASSED';
const _noCatch = 'NO_CATCH';
const _halfSecond = Duration(milliseconds: 500);

String _failOnce() {
  if (_logoutSucceeds) {
    return 'Success!';
  } else {
    _logoutSucceeds = true;
    throw Exception('Logout failed');
  }
}

bool _logoutSucceeds = false;


